<?xml version="1.0" ?>
<mujoco model="random_humanoid">
  <compiler angle="degree" inertiafromgeom="true"/>
  <default>
    <joint armature="1" damping="1" limited="true"/>
    <geom conaffinity="1" condim="1" contype="1" margin="0.001" material="geom" rgba="0.8 0.6 .4 1"/>
    <motor ctrllimited="true" ctrlrange="-.4 .4"/>
  </default>
  <option integrator="RK4" iterations="50" solver="PGS" timestep="0.003"/>
  <size nkey="5" nuser_geom="1"/>
  <visual>
    <map fogend="5" fogstart="3"/>
  </visual>
  <asset>
    <texture builtin="gradient" height="100" rgb1=".4 .5 .6" rgb2="0 0 0" type="skybox" width="100"/>
    <texture builtin="flat" height="1278" mark="cross" markrgb="1 1 1" name="texgeom" random="0.01" rgb1="0.8 0.6 0.4" rgb2="0.8 0.6 0.4" type="cube" width="127"/>
    <texture builtin="checker" height="100" name="texplane" rgb1="0 0 0" rgb2="0.8 0.8 0.8" type="2d" width="100"/>
    <material name="MatPlane" reflectance="0.5" shininess="1" specular="1" texrepeat="60 60" texture="texplane"/>
    <material name="geom" texture="texgeom" texuniform="true"/>
  </asset>
  <worldbody>
    <geom condim="3" friction="0.5315936670893011 .1 .1" type="plane" size="20 20 0.125" material="MatPlane" name="floor" pos="0 0 0" rgba="0.8 0.9 0.8 1"/>
    <body name="torso" pos="0 0 2.986416">
      <joint name="root" type="free" axis="0 1 0" armature="0.0" damping="0.0" stiffness="0.0"/>
      <geom name="torso1" pos="0 0 0" fromto="0 -0.116536 0 0 0.116536 0" size="0.136395" type="capsule"/>
      <geom name="head" pos="0 0 0.244467" size="0.095231" type="sphere"/>
      <geom name="uwaist" fromto="-0.012132 -0.11561 -0.306987 -0.012132 0.11561 -0.306987" size="0.155149" type="capsule"/>
      <body name="lwaist" pos="-0.000191 0 -0.567619">
        <joint name="abdomen_z" type="hinge" axis="0 0 1" armature="0.031026" damping="5.808712" stiffness="7.669154" range="-50.191013 49.056864"/>
        <joint name="abdomen_y" type="hinge" axis="0 1 0" armature="0.088956" damping="2.193426" stiffness="51.109861" range="-92.626769 35.190532"/>
        <geom name="lwaist1" type="capsule" fromto="-0.0 -0.156162 -0.0 0.0 0.156162 0.0" size="0.100077"/>
        <body name="pelvis" pos="0 0 -0.281477">
          <joint name="abdomen_x" type="hinge" axis="1 0 0" pos="0 0 0.206381" armature="0.094543" damping="3.282166" stiffness="24.238325" range="-45.647875 45.647875"/>
          <geom name="pelvis1" type="capsule" fromto="-0.0 -0.103452 -0.0 0.0 0.103452 0.0" size="0.165377"/>
          <body name="left_thigh" pos="-0.015156 0.106446 0.087729">
            <joint name="left_hip_x" type="hinge" axis="-1 0 0" armature="0.035422" damping="7.308159" stiffness="16.294453" range="-40.414994 11.16042"/>
            <joint name="left_hip_y" type="hinge" axis="0 1 0" armature="0.054032" damping="3.567601" stiffness="45.733609" range="-38.022653 41.172849"/>
            <joint name="left_hip_z" type="hinge" axis="0 0 -1" armature="0.054852" damping="1.691519" stiffness="47.860564" range="-124.274152 24.630554"/>
            <geom name="left_thigh1" type="capsule" fromto="0 0 0 0.0 -0.033721 -0.521345" size="0.066759"/>
            <body name="left_shin" pos="0 0 -0.606751">
              <joint name="left_knee" type="hinge" axis="1 0 0" armature="0.009214" damping="8.379477" stiffness="2.010979" range="-100.299528 -14.32432"/>
              <geom name="left_shin1" type="capsule" fromto="0 0 0 0.0 0.0 -0.544725" size="0.056827"/>
              <geom name="left_foot" pos="0 0 0.754053" size="0.137334" type="sphere" user="0"/>
            </body>
          </body>
          <body name="right_thigh" pos="-0.015156 -0.106446 0.087729">
            <joint name="right_hip_x" type="hinge" axis="1 0 0" armature="0.035422" damping="7.308159" stiffness="16.294453" range="-40.414994 11.16042"/>
            <joint name="right_hip_y" type="hinge" axis="0 1 0" armature="0.054032" damping="3.567601" stiffness="45.733609" range="-38.022653 41.172849"/>
            <joint name="right_hip_z" type="hinge" axis="0 0 1" armature="0.054852" damping="1.691519" stiffness="47.860564" range="-124.274152 24.630554"/>
            <geom name="right_thigh1" type="capsule" fromto="0 0 0 0.0 0.033721 -0.521345" size="0.066759"/>
            <body name="right_shin" pos="0 0 -0.606751">
              <joint name="right_knee" type="hinge" axis="1 0 0" armature="0.009214" damping="8.379477" stiffness="2.010979" range="-100.299528 -14.32432"/>
              <geom name="right_shin1" type="capsule" fromto="0 0 0 0.0 0.0 -0.544725" size="0.056827"/>
              <geom name="right_foot" pos="0 0 0.754053" size="0.137334" type="sphere" user="0"/>
            </body>
          </body>
        </body>
      </body>
      <body name="left_upper_arm" pos="0 0.187549 0.148903">
        <joint name="left_shoulder1" type="hinge" axis="2 -1 1" armature="0.012969" damping="1.413612" stiffness="20.301435" range="-92.122168 84.279241"/>
        <joint name="left_shoulder2" type="hinge" axis="0 1 1" armature="0.017923" damping="9.160915" stiffness="94.489678" range="-85.317382 89.538652"/>
        <geom name="left_upper_arm1" type="capsule" fromto="0 0 0 0.12124 0.12124 -0.12124" size="0.044078"/>
        <body name="left_lower_arm" pos="0.148816 0.148816 -0.148816">
          <joint name="left_elbow" type="hinge" axis="0 -1 -1" armature="0.001355" damping="5.44082" stiffness="2.098782" range="-84.894786 72.69781"/>
          <geom name="left_lower_arm1" type="capsule" fromto="0.028786 -0.028786 0.028786 0.028786 -0.028786 -0.344594" size="0.085398"/>
          <geom name="left_hand" pos="0.229645 -0.229645 0.229645" size="0.085091" type="sphere" user="0"/>
        </body>
      </body>
      <body name="right_upper_arm" pos="0 -0.187549 0.148903">
        <joint name="right_shoulder1" type="hinge" axis="2 1 1" armature="0.012969" damping="1.413612" stiffness="20.301435" range="-92.122168 84.279241"/>
        <joint name="right_shoulder2" type="hinge" axis="0 -1 1" armature="0.017923" damping="9.160915" stiffness="94.489678" range="-85.317382 89.538652"/>
        <geom name="right_upper_arm1" type="capsule" fromto="0 0 0 0.12124 -0.12124 -0.12124" size="0.044078"/>
        <body name="right_lower_arm" pos="0.148816 -0.148816 -0.148816">
          <joint name="right_elbow" type="hinge" axis="0 -1 1" armature="0.001355" damping="5.44082" stiffness="2.098782" range="-84.894786 72.69781"/>
          <geom name="right_lower_arm1" type="capsule" fromto="0.028786 0.028786 0.028786 0.028786 0.028786 -0.344594" size="0.085398"/>
          <geom name="right_hand" pos="0.229645 0.229645 0.229645" size="0.085091" type="sphere" user="0"/>
        </body>
      </body>
    </body>
  </worldbody>
  <tendon>
    <fixed name="left_hipknee">
      <joint coef="-0.743659" joint="left_hip_y"/>
      <joint coef="0.743659" joint="left_knee"/>
    </fixed>
    <fixed name="right_hipknee">
      <joint coef="-0.743659" joint="right_hip_y"/>
      <joint coef="0.743659" joint="right_knee"/>
    </fixed>
  </tendon>
  <actuator>
    <motor joint="abdomen_z" gear="55.225409" name="abdomen_z"/>
    <motor joint="abdomen_y" gear="55.225409" name="abdomen_y"/>
    <motor joint="abdomen_x" gear="55.225409" name="abdomen_x"/>
    <motor joint="left_hip_x" gear="98.562595" name="left_hip_x"/>
    <motor joint="left_hip_y" gear="237.56071" name="left_hip_y"/>
    <motor joint="left_hip_z" gear="54.840307" name="left_hip_z"/>
    <motor joint="left_knee" gear="206.573816" name="left_knee"/>
    <motor joint="left_shoulder1" gear="42.529014" name="left_shoulder1"/>
    <motor joint="left_shoulder2" gear="26.607782" name="left_shoulder2"/>
    <motor joint="left_elbow" gear="47.377464" name="left_elbow"/>
    <motor joint="right_hip_x" gear="98.562595" name="right_hip_x"/>
    <motor joint="right_hip_y" gear="237.56071" name="right_hip_y"/>
    <motor joint="right_hip_z" gear="54.840307" name="right_hip_z"/>
    <motor joint="right_knee" gear="206.573816" name="right_knee"/>
    <motor joint="right_shoulder1" gear="42.529014" name="right_shoulder1"/>
    <motor joint="right_shoulder2" gear="26.607782" name="right_shoulder2"/>
    <motor joint="right_elbow" gear="47.377464" name="right_elbow"/>
  </actuator>
</mujoco>
